<robot
  name="rep_ryw">
  <link
    name="base_link">
    <inertial>
      <origin
        xyz="-0.00040041 0.07848 1.4275"
        rpy="0 0 0" />
      <mass
        value="353.37" />
      <inertia
        ixx="133.11"
        ixy="1.5652"
        ixz="5.7253"
        iyy="137.3"
        iyz="-5.7873"
        izz="6.6505" />
    </inertial>
    <visual>
      <origin
        xyz="0 0 0"
        rpy="0 0 0" />
      <geometry>
        <mesh
          filename="package://rep_ryw/meshes/base_link.STL" />
      </geometry>
      <material
        name="">
        <color
          rgba="0.61569 0.64314 0.67451 1" />
      </material>
    </visual>
    <collision>
      <origin
        xyz="0 0 0"
        rpy="0 0 0" />
      <geometry>
        <mesh
          filename="package://rep_ryw/meshes/base_link.STL" />
      </geometry>
    </collision>
  </link>
  <link
    name="motor_Link">
    <inertial>
      <origin
        xyz="0.0051653 0.014164 1.8295E-17"
        rpy="0 0 0" />
      <mass
        value="2.1701" />
      <inertia
        ixx="0"
        ixy="0"
        ixz="0"
        iyy="0"
        iyz="0"
        izz="0" />
    </inertial>
    <visual>
      <origin
        xyz="0 0 0"
        rpy="0 0 0" />
      <geometry>
        <mesh
          filename="package://rep_ryw/meshes/motor_Link.STL" />
      </geometry>
      <material
        name="">
        <color
          rgba="0.61569 0.64314 0.67451 1" />
      </material>
    </visual>
    <collision>
      <origin
        xyz="0 0 0"
        rpy="0 0 0" />
      <geometry>
        <mesh
          filename="package://rep_ryw/meshes/motor_Link.STL" />
      </geometry>
    </collision>
  </link>
  <joint
    name="jt-m2b"
    type="revolute">
    <origin
      xyz="0 0.43 0.12633"
      rpy="-1.5708 -6.123E-17 -1.5708" />
    <parent
      link="base_link" />
    <child
      link="motor_Link" />
    <axis
      xyz="0 -1 0" />
    <limit
      effort="0"
      velocity="0" />
  </joint>
  <link
    name="wheel_Link">
    <inertial>
      <origin
        xyz="0 -0.025 1.4304E-18"
        rpy="0 0 0" />
      <mass
        value="0.80751" />
      <inertia
        ixx="0"
        ixy="0"
        ixz="0"
        iyy="0"
        iyz="0"
        izz="0" />
    </inertial>
    <visual>
      <origin
        xyz="0 0 0"
        rpy="0 0 0" />
      <geometry>
        <mesh
          filename="package://rep_ryw/meshes/wheel_Link.STL" />
      </geometry>
      <material
        name="">
        <color
          rgba="0.49804 0.49804 0.49804 1" />
      </material>
    </visual>
    <collision>
      <origin
        xyz="0 0 0"
        rpy="0 0 0" />
      <geometry>
        <mesh
          filename="package://rep_ryw/meshes/wheel_Link.STL" />
      </geometry>
    </collision>
  </link>
  <joint
    name="jt-w2m"
    type="continuous">
    <origin
      xyz="-0.025 0.08 0"
      rpy="2.44925315296973E-16 1.22460635382238E-16 1.5707963267949" />
    <parent
      link="motor_Link" />
    <child
      link="wheel_Link" />
    <axis
      xyz="0 0 1" />
  </joint>
  <link
    name="rwheel_Link">
    <inertial>
      <origin
        xyz="0 1.1102E-16 -0.075"
        rpy="0 0 0" />
      <mass
        value="0.54675" />
      <inertia
        ixx="0"
        ixy="0"
        ixz="0"
        iyy="0"
        iyz="0"
        izz="0" />
    </inertial>
    <visual>
      <origin
        xyz="0 0 0"
        rpy="0 0 0" />
      <geometry>
        <mesh
          filename="package://rep_ryw/meshes/rwheel_Link.STL" />
      </geometry>
      <material
        name="">
        <color
          rgba="0.49804 0.49804 0.49804 1" />
      </material>
    </visual>
    <collision>
      <origin
        xyz="0 0 0"
        rpy="0 0 0" />
      <geometry>
        <mesh
          filename="package://rep_ryw/meshes/rwheel_Link.STL" />
      </geometry>
    </collision>
  </link>
  <joint
    name="jt-rw2b"
    type="continuous">
    <origin
      xyz="-0.305 -0.93759 0.0063292"
      rpy="3.1416 -1.5708 0" />
    <parent
      link="base_link" />
    <child
      link="rwheel_Link" />
    <axis
      xyz="0 0 -1" />
  </joint>
  <link
    name="lwheel_Link">
    <inertial>
      <origin
        xyz="0 -1.1102E-16 -0.075"
        rpy="0 0 0" />
      <mass
        value="0.54675" />
      <inertia
        ixx="0"
        ixy="0"
        ixz="0"
        iyy="0"
        iyz="0"
        izz="0" />
    </inertial>
    <visual>
      <origin
        xyz="0 0 0"
        rpy="0 0 0" />
      <geometry>
        <mesh
          filename="package://rep_ryw/meshes/lwheel_Link.STL" />
      </geometry>
      <material
        name="">
        <color
          rgba="0.49804 0.49804 0.49804 1" />
      </material>
    </visual>
    <collision>
      <origin
        xyz="0 0 0"
        rpy="0 0 0" />
      <geometry>
        <mesh
          filename="package://rep_ryw/meshes/lwheel_Link.STL" />
      </geometry>
    </collision>
  </link>
  <joint
    name="jt-lw2b"
    type="continuous">
    <origin
      xyz="0.305 -0.93759 0.0063292"
      rpy="0 -1.5708 0" />
    <parent
      link="base_link" />
    <child
      link="lwheel_Link" />
    <axis
      xyz="0 0 1" />
  </joint>
  <link
    name="fork_Link">
    <inertial>
      <origin
        xyz="0.1638 -5.3071E-07 -0.37996"
        rpy="0 0 0" />
      <mass
        value="164.19" />
      <inertia
        ixx="2.17"
        ixy="-1.4273E-05"
        ixz="1.5204"
        iyy="3.4448"
        iyz="1.2533E-05"
        izz="1.2748" />
    </inertial>
    <visual>
      <origin
        xyz="0 0 0"
        rpy="0 0 0" />
      <geometry>
        <mesh
          filename="package://rep_ryw/meshes/fork_Link.STL" />
      </geometry>
      <material
        name="">
        <color
          rgba="0.61569 0.64314 0.67451 1" />
      </material>
    </visual>
    <collision>
      <origin
        xyz="0 0 0"
        rpy="0 0 0" />
      <geometry>
        <mesh
          filename="package://rep_ryw/meshes/fork_Link.STL" />
      </geometry>
    </collision>
  </link>
  <joint
    name="jt-f2b"
    type="prismatic">
    <origin
      xyz="0 0.105 0.91116"
      rpy="-5.4418E-17 5.4418E-17 -1.5708" />
    <parent
      link="base_link" />
    <child
      link="fork_Link" />
    <axis
      xyz="0 0 1" />
    <limit
      effort="0"
      velocity="0" />
  </joint>
  <link
    name="main_Link">
    <inertial>
      <origin
        xyz="-5.0336E-07 0.36638 0.35862"
        rpy="0 0 0" />
      <mass
        value="1088.2" />
      <inertia
        ixx="0"
        ixy="0"
        ixz="0"
        iyy="0"
        iyz="0"
        izz="0" />
    </inertial>
    <visual>
      <origin
        xyz="0 0 0"
        rpy="0 0 0" />
      <geometry>
        <mesh
          filename="package://rep_ryw/meshes/main_Link.STL" />
      </geometry>
      <material
        name="">
        <color
          rgba="0.61569 0.64314 0.67451 1" />
      </material>
    </visual>
    <collision>
      <origin
        xyz="0 0 0"
        rpy="0 0 0" />
      <geometry>
        <mesh
          filename="package://rep_ryw/meshes/main_Link.STL" />
      </geometry>
    </collision>
  </link>
  <joint
    name="jt-m2b"
    type="fixed">
    <origin
      xyz="-0.005 0.165 0.05"
      rpy="1.5708 -8.6736E-17 3.1416" />
    <parent
      link="base_link" />
    <child
      link="main_Link" />
    <axis
      xyz="0 0 0" />
  </joint>
  <link
    name="ffrwl_Link">
    <inertial>
      <origin
        xyz="-6.9389E-18 -0.075 0"
        rpy="0 0 0" />
      <mass
        value="0.54675" />
      <inertia
        ixx="0"
        ixy="0"
        ixz="0"
        iyy="0"
        iyz="0"
        izz="0" />
    </inertial>
    <visual>
      <origin
        xyz="0 0 0"
        rpy="0 0 0" />
      <geometry>
        <mesh
          filename="package://rep_ryw/meshes/ffrwl_Link.STL" />
      </geometry>
      <material
        name="">
        <color
          rgba="0.49804 0.49804 0.49804 1" />
      </material>
    </visual>
    <collision>
      <origin
        xyz="0 0 0"
        rpy="0 0 0" />
      <geometry>
        <mesh
          filename="package://rep_ryw/meshes/ffrwl_Link.STL" />
      </geometry>
    </collision>
  </link>
  <joint
    name="jt-ffrw2b"
    type="continuous">
    <origin
      xyz="-0.155 -1.0214 0.0063292"
      rpy="1.5708 1.5708 0" />
    <parent
      link="base_link" />
    <child
      link="ffrwl_Link" />
    <axis
      xyz="0 1 0" />
  </joint>
  <link
    name="fflwl_Link">
    <inertial>
      <origin
        xyz="6.0715E-18 0.075 0"
        rpy="0 0 0" />
      <mass
        value="0.54675" />
      <inertia
        ixx="0"
        ixy="0"
        ixz="0"
        iyy="0"
        iyz="0"
        izz="0" />
    </inertial>
    <visual>
      <origin
        xyz="0 0 0"
        rpy="0 0 0" />
      <geometry>
        <mesh
          filename="package://rep_ryw/meshes/fflwl_Link.STL" />
      </geometry>
      <material
        name="">
        <color
          rgba="0.49804 0.49804 0.49804 1" />
      </material>
    </visual>
    <collision>
      <origin
        xyz="0 0 0"
        rpy="0 0 0" />
      <geometry>
        <mesh
          filename="package://rep_ryw/meshes/fflwl_Link.STL" />
      </geometry>
    </collision>
  </link>
  <joint
    name="jt-fflw2b"
    type="continuous">
    <origin
      xyz="0.155 -1.0214 0.0063292"
      rpy="1.5708 1.5708 0" />
    <parent
      link="base_link" />
    <child
      link="fflwl_Link" />
    <axis
      xyz="0 1 0" />
  </joint>
</robot>